Workbook

Sheet pagos febrero
A1: DETALLE DE PAGOS EN BANCO
C3: MES DE FEBERO DE 2025
A4: Cuenta:Alborada 04-11-00-000468-4
A8: Fecha | B8: Recibo | C8: Descripción | D8: No.Casa | E8: Pagos | F8: Saldo total | G8: Columna1 | J8: Fecha | K8: Casa | L8: Recibo | M8: NOMBRE | N8: Monto
A9: 45696.354 | B9: 16701 al 16726 | C9: BANCA MOVIL TRANSFERENCIA DE 0427120001653 DAYRA LUCILA CANALES de SWANSTON ENTRE CUENTAS | E9: 52 | F9: 52 | G9: a | J9: 45694 | K9: 205 | L9: 16701 | M9: JAIME PEREZ | N9: 2 | O9: a
A10: 45696.354 | B10: 16727 | C10: YAPPY DE YOLANDA ENEIDA LOPER ALABARCA POR mantenimiento enero 2025 casa 271 | D10: 271 | E10: 20 | F10: =+F9+Tabla25[[#This Row],[Pagos]] -> 72 | G10: a | J10: 45695 | K10: 193 | L10: 16702 | M10: NURIA ELENA JIMENEZ de ABREGO | N10: 2 | O10: a
A11: 45696.354 | B11: 16728 | C11: YAPPY DE MARIA DE LOS ANGELES MONTENEGRO DE LEON POR cuota mes de enero 2025 | D11: 14 | E11: 15 | F11: =+F10+Tabla25[[#This Row],[Pagos]] -> 87 | G11: a | J11: 45695 | K11: 177 | L11: 16703 | M11: JOEL ALBERTO BELFORD PETERS | N11: 2 | O11: a
A12: 45696.354 | B12: 16729 | C12: YAPPY DE VIELKA LUZMILA CUSATTI ANAYA POR Pago de Mantenimiento casa 20 calle primer este | D12: 20 | E12: 20 | F12: =+F11+Tabla25[[#This Row],[Pagos]] -> 107 | G12: a | J12: 45695 | K12: 58 | L12: 16704 | M12: ODALIS DE MENESES | N12: 2 | O12: a
A13: 45696.354 | B13: 16730 | C13: YAPPY DE JAIME ALBERTO PEREZ MERO | D13: 205 | E13: 20 | F13: =+F12+Tabla25[[#This Row],[Pagos]] -> 127 | G13: a | J13: 45695 | K13: 179 | L13: 16705 | M13: ALMA IFIL | N13: 2 | O13: a
A14: 45696.354 | B14: 16731 | C14: YAPPY DE SHARYN TAVANE DELGADO ROWE POR Casa 199 pago mes de enero Sharyn Delgado | D14: 199 | E14: 15 | F14: =+F13+Tabla25[[#This Row],[Pagos]] -> 142 | G14: a | J14: 45695 | K14: 166 | L14: 16706 | M14: NATALIA KATIUSKA WARDROPE SANCHEZ | N14: 2 | O14: a
A15: 45696.354 | B15: 16732 | C15: YAPPY DE DAIZA BRU TORRES | D15: 143 | E15: 15 | F15: =+F14+Tabla25[[#This Row],[Pagos]] -> 157 | G15: a | J15: 45695 | K15: 8 | L15: 16707 | M15: DARINKA DANISETT DE HOYOS LOPEZ | N15: 2 | O15: a
A16: 45696.354 | B16: 16733 | C16: YAPPY DE JERONIMO VALENTIN HERNANDEZ CHIN | D16: 54 | E16: 15 | F16: =+F15+Tabla25[[#This Row],[Pagos]] -> 172 | G16: a | J16: 45695 | K16: 54 | L16: 16708 | M16: JERONIMO VALENTIN HERNANDEZ CHIN | N16: 2 | O16: a
A17: 45697.354 | B17: 16734 | C17: YAPPY DE JOANNA VANESSA EVERSLEY DE VALDES POR casa71 mes enero 2025 | D17: 71 | E17: 15 | F17: =+F16+Tabla25[[#This Row],[Pagos]] -> 187 | G17: a | J17: 45695 | K17: 75 | L17: 16709 | M17: VANESSA VICTORIA PARNTHER LUZCANDO | N17: 2 | O17: a
A18: 45697.354 | B18: 16735 | C18: YAPPY DE QUERUBI LIZET NEREIDA de HILTON | D18: 19 | E18: 15 | F18: =+F17+Tabla25[[#This Row],[Pagos]] -> 202 | G18: a | J18: 45695 | K18: 6 | L18: 16710 | M18: MIGUEL ROGELIO SANCHEZ PALACIO | N18: 2 | O18: a
A19: 45698.354 | B19: 16736 | C19: transferencia Iluminada Bonilla - casa 167- enero 2025 | D19: 167 | E19: 15 | F19: =+F18+Tabla25[[#This Row],[Pagos]] -> 217 | G19: a | J19: 45695 | K19: 117 | L19: 16711 | M19: SARALIZ LORENA HUSBAND DE VELASQUEZ | N19: 2 | O19: a
A20: 45698 | B20: 16737 | C20: fla ibarguen casa 21 enero | D20: 21 | E20: 15 | F20: =+F19+Tabla25[[#This Row],[Pagos]] -> 232 | G20: a | J20: 45695 | K20: 49 | L20: 16712 | M20: TAIRIN TATIANA ROBINSON de LASSONDE | N20: 2 | O20: a
A21: 45698.354 | B21: 16738 | C21: YAPPY DE GREGORIA HEIDI BRYAN RAMOS POR pago enero febrero casa196 | D21: 196 | E21: 30 | F21: =+F20+Tabla25[[#This Row],[Pagos]] -> 262 | G21: a | J21: 45695 | K21: 119 | L21: 16713 | M21: IRASEMA ESTHER MURILLO DE SMALL | N21: 2 | O21: a
... A27: 45700.354 | B27: 16744 | C27: BANCA MOVIL TRANSFERENCIA DE YISEL BONET ALTAMIRANDA de YARD pago mes de enero y feb casa | D27: 156 | E27: 30 | F27: =+F26+Tabla25[[#This Row],[Pagos]] -> 442 | G27: a | J27: 45695 | K27: 278 | L27: 16719 | M27: YAMILKA TUÑON ALCAZAR | N27: 2 | O27: a
A28: 45701.354 | B28: 16745 | C28: YAPPY DE ILKA MELISA MARK HOY | D28: 59 | E28: 15 | F28: =+F27+Tabla25[[#This Row],[Pagos]] -> 457 | G28: a | J28: 45695 | K28: D-9 | L28: 16720 | M28: ADELSA AYARIS AGUILAR ALVARADO | N28: 2 | O28: a
A29: 45701.354 | B29: 16746 | C29: BANCA MOVIL TRANSFERENCIA DE JOSE ALEJANDRO BARROWS ROBINSON casa 154 | D29: 154 | E29: 30 | F29: =+F28+Tabla25[[#This Row],[Pagos]] -> 487 | G29: a | J29: 45695 | K29: 130 | L29: 16721 | M29: ENRIQUE JOSE MARCANO GOMEZ | N29: 2 | O29: a
A30: 45702.354 | B30: 16747 | C30: BANCA MOVIL TRANSFERENCIA DE 0427120001653 DAYRA LUCILA CANALES de SWANSTON casa 50 Pablo Mejia | D30: 50 | E30: 15 | F30: =+F29+Tabla25[[#This Row],[Pagos]] -> 502 | G30: a | J30: 45695 | K30: 254 | L30: 16722 | M30: TATEANA JAEN | N30: 2 | O30: a
A31: 45702.354 | B31: 16748 | C31: BANCA EN LINEA TRANSFERENCIA DE LINDA YAJAIRA LAJON ANDERSON Pago seguridad Casa 219 enero | D31: 219 | E31: 30 | F31: =+F30+Tabla25[[#This Row],[Pagos]] -> 532 | G31: a | J31: 45695 | K31: 199 | L31: 16723 | M31: SHARYN TAVANE DELGADO ROWE | N31: 2 | O31: a
A32: 45702.354 | B32: 16749 | C32: YAPPY DE MARTIN LUIS MENESES TESIS POR FLIA Meneses 58 | D32: 58 | E32: 15 | F32: =+F31+Tabla25[[#This Row],[Pagos]] -> 547 | G32: a | J32: 45695 | K32: 140 | L32: 16724 | M32: FERNANDO NOAH ROSALES | N32: 2 | O32: a
A33: 45702.354 | B33: 16750 | C33: YAPPY DE PORFIRIO JUSTAVINO CEDEÑO | D33: 289 | E33: 30 | F33: =+F32+Tabla25[[#This Row],[Pagos]] -> 577 | G33: a | J33: 45695 | K33: 167 | L33: 16725 | M33: ILUMINADA BONILLA VIDAL | N33: 2 | O33: a
A34: 45703.354 | B34: 16751 | C34: BANCA MOVIL TRANSFERENCIA DE ROLANDO RODRIGO SIMS PEREZ Casa 314 enero y febrero 2025 | D34: 314 | E34: 30 | F34: =+F33+Tabla25[[#This Row],[Pagos]] -> 607 | G34: a | J34: 45695 | K34: 168 | L34: 16726 | M34: ILUMINADA BONILLA VIDAL | N34: 2 | O34: a
A35: 45703.354 | B35: 16752 | C35: BANCA MOVIL TRANSFERENCIA DE NORMA JAY SKERRITT VALENTINE Pago de seguridad ene y feb 2025 | D35: D-05 | E35: 30 | F35: =+F34+Tabla25[[#This Row],[Pagos]] -> 637 | G35: a
A36: 45703.354 | B36: 16753 | C36: YAPPY DE DAIZA BRU TORRES | D36: 143 | E36: 15 | F36: =+F35+Tabla25[[#This Row],[Pagos]] -> 652 | G36: a | N36: =SUM(N9:N34) -> 52
A37: 45703.354 | B37: 16754 | C37: BANCA MOVIL TRANSFERENCIA DE LUIS ENRIQUE AMADOR MARTINEZ A TERCEROS | D37: 195 | E37: 15 | F37: =+F36+Tabla25[[#This Row],[Pagos]] -> 667 | G37: a
A38: 45704.354 | B38: 16755 | C38: BANCA MOVIL TRANSFERENCIA DE DAYANARA ITZEL BENJAMIN DE DE LEON mens casa D 12 Flia De Leo | D38: D-12 | E38: 15 | F38: =+F37+Tabla25[[#This Row],[Pagos]] -> 682 | G38: a
A39: 45704.354 | B39: 16756 | C39: BANCA MOVIL TRANSFERENCIA DE CELIA ESTHER SALAZAR de PAULT Mes de enero casa 183 | D39: 183 | E39: 15 | F39: =+F38+Tabla25[[#This Row],[Pagos]] -> 697 | G39: a
A40: 45704.354 | B40: 16757 | C40: YAPPY DE JAIME ALBERTO PEREZ MERO | D40: 205 | E40: 15 | F40: =+F39+Tabla25[[#This Row],[Pagos]] -> 712 | G40: a
A41: 45704.354 | B41: 16758 | C41: YAPPY DE VANESSA VICTORIA PARNTHER LUZCANDO POR Mant casa 75 enero 2025 | D41: 75 | E41: 15 | F41: =+F40+Tabla25[[#This Row],[Pagos]] -> 727 | G41: a
A42: 45704.354 | B42: 16759 | C42: YAPPY DE MARTIN LUIS MENESES TESIS POR casa 57 Piedad del Cid | D42: 57 | E42: 15 | F42: =+F41+Tabla25[[#This Row],[Pagos]] -> 742 | G42: a
A43: 45704.354 | B43: 16760 | C43: YAPPY DE YARITZA YAMILKA COOPER CHIFUNDO POR Casa 202 Mes de Enero 2025 Schifundo - YCoope | D43: 202 | E43: 15 | F43: =+F42+Tabla25[[#This Row],[Pagos]] -> 757 | G43: a
A44: 45705.354 | B44: 16761 | C44: BANCA MOVIL TRANSFERENCIA DE ADELSA AYARIS AGUILAR ALVARADO casa D9 | D44: D9 | E44: 30 | F44: =+F43+Tabla25[[#This Row],[Pagos]] -> 787 | G44: a
A45: 45705.354 | B45: 16762 | C45: Magaly de Vivero | D45: 145 | E45: 15 | F45: =+F44+Tabla25[[#This Row],[Pagos]] -> 802 | G45: a
A46: 45705.354 | B46: 16763 | C46: BANCA MOVIL TRANSFERENCIA DE NILKA LORENA DEL CASTILLO ZELAYA seguridad y mantenimiento ca | D46: 135 | E46: 30 | F46: =+F45+Tabla25[[#This Row],[Pagos]] -> 832 | G46: a
A47: 45705.354 | B47: 16764 | C47: YAPPY DE YOLANDA ENEIDA LOPER ALABARCA POR mantenimiento febrero 2025 casa 271 | D47: 271 | E47: 20 | F47: =+F46+Tabla25[[#This Row],[Pagos]] -> 852 | G47: a
A48: 45705.354 | B48: 16765 | C48: YAPPY DE JAZMINA ITZEL VEGA de SMITH POR seguridad y Mant enero y feb 2025 casa 328 n | D48: 328 | E48: 30 | F48: =+F47+Tabla25[[#This Row],[Pagos]] -> 882 | G48: a
A49: 45705.354 | B49: 16766 | C49: YAPPY DE EDGAR PAUL ORTEGA PIMENTEL POR Mant Casa 323 Flia Ortega Ene y Feb | D49: 323 | E49: 30 | F49: =+F48+Tabla25[[#This Row],[Pagos]] -> 912 | G49: a
...

Sheet pagos marzo 2025
A1: DETALLE DE PAGOS EN BANCO
B2: MES DE MARZO DE 2025
A4: Cuenta:Alborada 04-11-00-000468-4
A8: Fecha | B8: Recibo | C8: Descripción | D8: No.Casa | E8: Pagos | F8: Saldo total
A10: 45716.375 | C10: SALDO AL 28 DE FEBRERO DE 2025 | E10: 1517.42 | F10: =+E10 -> 1517.42
A11: 45717.375 | B11: 16819 | C11: YAPPY DE ROBERTO RODRIGUEZ PEREIRA POR Paga casa 43 familia Rodriguez enero y febrero | D11: 43 | E11: 30 | F11: =+F13+E11 -> 1622.42 | G11: a
A12: 45717.375 | B12: 16820 | C12: EFECTIVO FLIA VANEGAS -CASA 200 ENERO -FEBRERO Y MARZO | D12: 200 | E12: 45 | F12: =+F10+E12 -> 1562.42 | G12: a
A13: 45717.375 | B13: 16821 | C13: EFECTIVO DELANO SANDERS - CASA 285 FEBRERO Y MARZO | D13: 285 | E13: 30 | F13: =+F12+E13 -> 1592.42 | G13: a
A14: 45717.375 | B14: 16822 | C14: YAPPY DE PASTOR CAMARENA SMITH | D14: D-10 | E14: 30 | F14: =+F11+E14 -> 1652.42 | G14: a
A15: 45718.375 | B15: 16823 | C15: YAPPY DE JULIO ENRIQUE MEJIA POR Seguridad y mantenimiento Casa 291 Flia Mejia Nino | D15: 291 | E15: 30 | F15: =+F14+E15 -> 1682.42 | G15: a
A16: 45718.375 | B16: 16824 | C16: BANCA MOVIL TRANSFERENCIA DE LEOPOLDO QUINTERO VALDES (O) LUZMILA ELENA PORTER DE QUINTER | D16: 47 | E16: 30 | F16: =+F15+E16 -> 1712.42 | G16: a
A17: 45718.375 | B17: 16825 | C17: YAPPY DE YAVIRITZEL DEL CARMEN PANAY POR Enero y febrero casa 187 | D17: 187 | E17: 30 | F17: =+F16+E17 -> 1742.42 | G17: a
A18: 45718.375 | B18: 16826 | C18: YAPPY DE YESICA MARLENE CHIFUNDO DE PRESTAN POR Seguridad y mantenimiento de casa 210 Flia | D18: 210 | E18: 30 | F18: =+F17+E18 -> 1772.42 | G18: a
A19: 45718.375 | B19: 16827 | C19: YAPPY DE SARALIZ LORENA HUSBAND DE VELASQUEZ POR casa 117 tercera oeste flia Velasquez | D19: 117 | E19: 30 | F19: =+F18+E19 -> 1802.42 | G19: a
A20: 45718.375 | B20: 16828 | C20: YAPPY DE SUMAYKIRA YANILET GRENALD FERREIRA POR Pago de Casa 136 familia Grenald mantenimi | D20: 136 | E20: 30 | F20: =+F19+E20 -> 1832.42 | G20: a
A21: 45718.375 | B21: 16829 | C21: YAPPY DE NATIVIDAD SANCHEZ DE FORBES | D21: 175 | E21: 30 | F21: =+F20+E21 -> 1862.42 | G21: a
A22: 45718.375 | B22: 16830 | C22: YAPPY DE ISAIAS FRANCISCO TATE BENJAMIN POR mes de enero casa 239 Tate | D22: 239 | E22: 15 | F22: =+F21+E22 -> 1877.42 | G22: a
A23: 45718.375 | B23: 16831 | C23: YAPPY DE YARITZA YAMILKA COOPER CHIFUNDO POR Mes de febrero Casa 202 Silvina Chifundo Yari | D23: 202 | E23: 15 | F23: =+F22+E23 -> 1892.42 | G23: a
A24: 45718.375 | B24: 16832 | C24: YAPPY DE ANTONIO ALCEDO AGUIRRE POR Casa 217 Enero | D24: 217 | E24: 15 | F24: =+F23+E24 -> 1907.42 | G24: a
A25: 45718.375 | B25: 16833 | C25: BANCA MOVIL TRANSFERENCIA DE FELICIA OLIVIA GITTENS MERCHANT Casa 40 Flia GittensZachary m | D25: 40 | E25: 45 | F25: =+F24+E25 -> 1952.42 | G25: a
A26: 45718.375 | B26: 16834 | C26: BANCA MOVIL TRANSFERENCIA DE NATIVIDAD VALENCIA de JIMENEZ mantenimiento de marzo Casa N 2 | D26: 26 | E26: 15 | F26: =+F25+E26 -> 1967.42 | G26: a
... A50: 45722 | B50: 16858 | C50: Luis Levy - mant. -febrero | D50: 234 | E50: 15 | F50: =+F49+E50 -> 2487.42 | G50: a
B51: 16859 | C51: recibo reemplazo recibo 16775 del 18/02/2025 | E51: 0 | F51: =+F50+E51 -> 2487.42 | G51: a
A52: 45724 | B52: 16860 | C52: Delano Saunders - mant, enero | D52: 285 | E52: 15 | F52: =+F51+E52 -> 2502.42 | G52: a
A53: 45724 | B53: 16861 | C53: Pablo Mejia - mant. Marzo y abril | D53: 50 | E53: 30 | F53: =+F52+E53 -> 2532.42 | G53: a
A54: 45724 | B54: 16862 | C54: Ilka Mack -mant-marzo | D54: 59 | E54: 15 | F54: =+F53+E54 -> 2547.42 | G54: a
A55: 45724 | B55: 16863 | C55: Flia. Mc Laughlin - mant. Enero y febrero | D55: 161 | E55: 30 | F55: =+F54+E55 -> 2577.42 | G55: a
A56: 45721 | B56: 16864 | C56: BANCA MOVIL TRANSFERENCIA DE TAMARA YEZENIA CATUY de PACHECO SEG ENERO FEBRERO MARZO C160 | D56: 160 | E56: 45 | F56: =+F55+E56 -> 2622.42 | G56: a
A57: 45722 | B57: 16865 | C57: BANCA MOVIL TRANSFERENCIA DE MARLENE BOYCE DAWKINS casa 181 Enero y febrero | D57: 181 | E57: 30 | F57: =+F56+E57 -> 2652.42 | G57: a
A58: 45722 | B58: 16866 | C58: YAPPY DE YOLANDA ENEIDA LOPER ALABARCA POR mantenimiento marzo 2025 casa 271 | D58: 271 | E58: 20 | F58: =+F57+E58 -> 2672.42 | G58: a
A59: 45722 | B59: 16867 | C59: ACH - YOHANA LISBETH MOLINAR MARIN DE GONDOLA- febrero | D59: 113 | E59: 15 | F59: =+F58+E59 -> 2687.42 | G59: a
A60: 45722 | B60: 16868 | C60: YAPPY DE MARTHA BIBIANA ACOSTA MARULANDA POR casa 105 familia Estrada meses de enero a mar | D60: 105 | E60: 45 | F60: =+F59+E60 -> 2732.42 | G60: a
A61: 45722 | B61: 16869 | C61: YAPPY DE IRASEMA ESTHER MURILLO DE SMALL | D61: 119 | E61: 30 | F61: =+F60+E61 -> 2762.42 | G61: a
A62: 45722 | B62: 16870 | C62: YAPPY DE MIOZOTIS DEL CARMEN OLMOS LARA- marzo | D62: 10 | E62: 15 | F62: =+F61+E62 -> 2777.42 | G62: a
A63: 45723 | B63: 16871 | C63: YAPPY DE YAZMIN DAMARIS SOTO PIMENTEL | D63: 162 | E63: 30 | F63: =+F62+E63 -> 2807.42 | G63: a
... A97: 45733 | B97: 16905 | C97: AURA HURTADO - ENERO A MARZO | D97: 9 | E97: 45 | F97: =+F96+E97 -> 4047.42 | G97: a
B98: 16906 | C98: ANULADO | F98: =+F97+E98 -> 4047.42 | G98: a
B99: 16907 | C99: ANULADO | F99: =+F98+E99 -> 4047.42 | G99: a
A100: 45727.8 | B100: 16908 | C100: BANCA MOVIL TRANSFERENCIA DE DAMARIS ESTHER SARMIENTO de MARTINEZ CASA 324 MARTINEZ SARMIE -ENERO Y FEBRERO | D100: 324 | E100: 30 | F100: =+F99+E100 -> 4077.42 | G100: a
A101: 45727.8 | B101: 16909 | C101: BANCA MOVIL TRANSFERENCIA DE GISELA GONZALEZ QUIROZ Casa 88 Gisela Gonzalez Enero a Abril | D101: 88 | E101: 60 | F101: =+F100+E101 -> 4137.42 | G101: a
...

Sheet pagos abril 2025
A1: DETALLE DE PAGOS EN BANCO
B2: MES DE ABRIL DE 2025
A4: Cuenta:Alborada 04-11-00-000468-4
A8: Fecha | B8: Recibo | C8: Descripción | D8: No.Casa | E8: Pagos | F8: Saldo total
A11: 45748.327 | B11: 17057 | C11: BANCA MOVIL TRANSFERENCIA DE NELSON AZARIAS MORENO MAGDALENO pago de mantenimiento la albo | D11: 310 | E11: 15 | F11: =+'abril Saraliz'!G9+E11 -> 4926.93 | G11: a
A12: 45748.327 | B12: 17058 | C12: BANCA MOVIL TRANSFERENCIA DE LUIS ENRIQUE AMADOR MARTINEZ Pago Seguridad mes Abril | D12: 195 | E12: 15 | F12: =+F11+E12 -> 4941.93 | G12: a
A13: 45748.327 | B13: 17059 | C13: BANCA EN LINEA TRANSFERENCIA DE 0427120001653 DAYRA LUCILA CANALES de SWANSTON casa 306 ro | D13: 306 | E13: 30 | F13: =+F12+E13 -> 4971.93 | G13: a
A14: 45748.327 | B14: 17060 | C14: YAPPY DE VANESSA VICTORIA PARNTHER LUZCANDO POR Mant casa 28 flia Sanchez Ene y Febrero ca | D14: 28 | E14: 30 | F14: =+F13+E14 -> 5001.93 | G14: a
A15: 45748.327 | B15: 17061 | C15: YAPPY DE GUILLERMO CHALHOUB RODRIGUEZ POR Marzo y Abril 2025 Casa 250 Alborada | D15: 250 | E15: 30 | F15: =+F14+E15 -> 5031.93
A16: 45748.327 | B16: 17062 | C16: YAPPY DE MARTIN LUIS MENESES TESIS POR casa 58 FLIA Meneses | D16: 58 | E16: 15 | F16: =+F15+E16 -> 5046.93
A17: 45748.327 | B17: 17063 | C17: YAPPY DE KAISHA TAMARA RIVAS JULIO -casa 79 | D17: 79 | E17: 15 | F17: =+F16+E17 -> 5061.93
A18: 45748.327 | B18: 17064 | C18: YAPPY DE PORFIRIO JUSTAVINO CEDEÑO | D18: 289 | E18: 15 | F18: =+F17+E18 -> 5076.93
A19: 45748.327 | B19: 17065 | C19: BANCA MOVIL TRANSFERENCIA DE LEOPOLDO QUINTERO VALDES (O) LUZMILA ELENA PORTER DE QUINTER | D19: 47 | E19: 15 | F19: =+F18+E19 -> 5091.93
A20: 45748.327 | B20: 17066 | C20: YAPPY DE SUNILA GITA PATEL SALDAÑA POR Casa 29 josefina de Patel mant febrero y marzo 2025 | D20: 29 | E20: 30 | F20: =+F19+E20 -> 5121.93
A21: 45749.327 | B21: 17067 | C21: BANCA MOVIL TRANSFERENCIA DE 0427120001653 DAYRA LUCILA CANALES de SWANSTON casa 278 enero | D21: 278 | E21: 30 | F21: =+F20+E21 -> 5151.93
A22: 45749.327 | B22: 17068 | C22: YAPPY DE ANTONIO ALCEDO AGUIRRE POR Casa 217 abril | D22: 217 | E22: 15 | F22: =+F21+E22 -> 5166.93
A23: 45749.327 | B23: 17069 | C23: YAPPY DE OSVALDO HERRERA CARRIAZO POR Mes de Abril casa 53 Flia Herrera | D23: 53 | E23: 15 | F23: =+F22+E23 -> 5181.93
F24: =+F23+E24 -> 5181.93

Sheet abril Saraliz
A2: Últimos movimientos
A4: Cuenta:ALBORADA 04-11-00-000468-4
A8: Fecha | B8: Recibo | C8: Descripción | D8: Casa | E8: Crédito | G8: Saldo total
A9: 45747 | C9: SALDO AL 31 DE MARZO DE 2025 | E9: =+'pagos marzo 2025'!F261 -> 4911.93 | G9: =+E9 -> 4911.93
A10: 45748.1 | B10: 17058 | C10: BANCA MOVIL TRANSFERENCIA DE NELSON AZARIAS MORENO MAGDALENO pago de mantenimiento la albo | D10: 310 | E10: 15 | G10: =+G9+E10+F10 -> 4926.93
A11: 45748.1 | B11: 17059 | C11: BANCA MOVIL TRANSFERENCIA DE LUIS ENRIQUE AMADOR MARTINEZ Pago Seguridad mes Abril | D11: 195 | E11: 15 | G11: =+G10+E11+F11 -> 4941.93
A12: 45748.1 | B12: 17060 | C12: BANCA EN LINEA TRANSFERENCIA DE 0427120001653 DAYRA LUCILA CANALES de SWANSTON casa 306 ro | D12: 306 | E12: 30 | G12: =+G11+E12+F12 -> 4971.93
A13: 45748.1 | B13: 17061 | C13: YAPPY DE VANESSA VICTORIA PARNTHER LUZCANDO POR Mant casa 28 flia Sanchez Ene y Febrero ca | D13: 28 | E13: 30 | G13: =+G12+E13+F13 -> 5001.93
A14: 45748.1 | B14: 17062 | C14: YAPPY DE GUILLERMO CHALHOUB RODRIGUEZ POR Marzo y Abril 2025 Casa 250 Alborada | D14: 250 | E14: 30 | G14: =+G13+E14+F14 -> 5031.93
A15: 45748.1 | B15: 17063 | C15: YAPPY DE MARTIN LUIS MENESES TESIS POR casa 58 FLIA Meneses | D15: 58 | E15: 15 | G15: =+G14+E15+F15 -> 5046.93
A16: 45748.1 | B16: 17064 | C16: YAPPY DE KAISHA TAMARA RIVAS JULIO | D16: 79 | E16: 15 | G16: =+G15+E16+F16 -> 5061.93
A17: 45748.1 | B17: 17065 | C17: YAPPY DE PORFIRIO JUSTAVINO CEDEÑO | D17: 289 | E17: 15 | G17: =+G16+E17+F17 -> 5076.93
A18: 45748.1 | B18: 17066 | C18: BANCA MOVIL TRANSFERENCIA DE LEOPOLDO QUINTERO VALDES (O) LUZMILA ELENA PORTER DE QUINTER | D18: 47 | E18: 15 | G18: =+G17+E18+F18 -> 5091.93
A19: 45748.1 | B19: 17067 | C19: YAPPY DE SUNILA GITA PATEL SALDAÑA POR Casa 29 josefina de Patel mant febrero y marzo 2025 | D19: 29 | E19: 30 | G19: =+G18+E19+F19 -> 5121.93
A20: 45749.1 | B20: 17068 | C20: BANCA MOVIL TRANSFERENCIA DE 0427120001653 DAYRA LUCILA CANALES de SWANSTON casa 278 enero | D20: 278 | E20: 30 | G20: =+G19+E20+F20 -> 5151.93
A21: 45749.1 | B21: 17069 | C21: YAPPY DE ANTONIO ALCEDO AGUIRRE POR Casa 217 abril | D21: 217 | E21: 15 | G21: =+G20+E21+F21 -> 5166.93
A22: 45749.1 | B22: 17070 | C22: YAPPY DE OSVALDO HERRERA CARRIAZO POR Mes de Abril casa 53 Flia Herrera | D22: 53 | E22: 15 | G22: =+G21+E22+F22 -> 5181.93
A23: 45759.069 | B23: 17071, 17072,17073, 17074,17075, 17087, 17094, 17096, 17101, 17102, 17105 | C23: DEPOSITO CUENTA DE AHORROS SIN LIBRETA DEPOSITADO POR SARALIZ CASAS: 59, 179, 285, 4, 116, 294, 57, 55, 334, 318, 246 | D23: VARIAS CASAS | E23: 360 | G23: =+G22+E23+F23 -> 5541.93
A24: 45750.1 | B24: 17076 | C24: YAPPY DE ELOISA MALENY JAEN GUTIERREZ | D24: 185 | E24: 15 | G24: =+G23+E24+F24 -> 5556.93
A25: 45749.1 | B25: 17077 | C25: YAPPY DE NITZIA ITZEL AGUILAR GALVAN POR mes de abril Familia Aguilar Casa 56 | D25: 56 | E25: 15 | G25: =+G24+E25+F25 -> 5571.93
A26: 45749.1 | B26: 17078 | C26: YAPPY DE YOLANDA ENEIDA LOPER ALABARCA POR mantenimiento casa 271 abril 2025 | D26: 271 | E26: 20 | G26: =+G25+E26+F26 -> 5591.93
A27: 45749.1 | B27: 17079 | C27: YAPPY DE YANETH YAMILKA BADILLA PINEDA POR cuota abril casa 157 Yaneth Badilla | D27: 157 | E27: 15 | G27: =+G26+E27+F27 -> 5606.93
A28: 45749.1 | B28: 17080 | C28: YAPPY DE YURIBETH YAILYN LEE | D28: 64 | E28: 30 | G28: =+G27+E28+F28 -> 5636.93
A29: 45750.1 | B29: 17081 | C29: ACH - DEMETRIO CELSO PRESCOTT RODRIGUEZ | D29: 241 | E29: 15 | G29: =+G28+E29+F29 -> 5651.93
A30: 45749.1 | B30: 17082 | C30: YAPPY DE YUMITZIE ANNELIS HARWOOD de CEDEÑO POR mes de marzo casa 192 Flia Cedeno | D30: 192 | E30: 15 | G30: =+G29+E30+F30 -> 5666.93
A31: 45750.1 | B31: 17083 | C31: YAPPY DE TAIRIN TATIANA ROBINSON de LASSONDE | D31: 49 | E31: 15 | G31: =+G30+E31+F31 -> 5681.93
A32: 45750.1 | B32: 17084 | C32: ACH - DENNIS BARNES GRAHAM | D32: 148 | E32: 15 | G32: =+G31+E32+F32 -> 5696.93
A33: 45750.1 | B33: 17085 | C33: YAPPY DE ANSELMO EMILIANO FORDE CHRISTOPHER | D33: 5 | E33: 15 | G33: =+G32+E33+F33 -> 5711.93
A34: 45750.1 | B34: 17086 | C34: YAPPY DE SARALIZ LORENA HUSBAND DE VELASQUEZ POR casa 117 marzo y abril flia velasquez | D34: 117 | E34: 30 | G34: =+G33+E34+F34 -> 5741.93 | K34: DEPOSITADO 12 DE ABRIL
A35: 45750.1 | B35: COMPRA | C35: BANCA MOVIL TRANSFERENCIA A 0311010007897 COPYMATIC (CONSORCIO EJECUTIVO, S.A.) LIBRO RECO | D35: _ | F35: -21.35 | G35: =+G34+E35+F35 -> 5720.58 | K35: CASA | L35: MONTO | M35: RECIBOS
A36: 45750.1 | B36: PAGO | C36: BANCA MÓVIL TIGO HOGAR - PYME (88280329) | D36: _ | F36: -90.19 | G36: =+G35+E36+F36 -> 5630.39 | K36: 59 | L36: 30 | M36: 17071
A37: 45750.1 | B37: PAGO | C37: BANCA MÓVIL ENSA (ELEKTRA NORESTE) (000000882669) | D37: _ | F37: -22.68 | G37: =+G36+E37+F37 -> 5607.71 | K37: 179 | L37: 30 | M37: 17072
A38: 45750.1 | B38: 17231 | C38: familia vivero casa 145 | D38: 145 | E38: 15 | G38: =+G37+E38+F38 -> 5622.71 | K38: 285 | L38: 15 | M38: 17073
A39: 45751.1 | B39: 17088 | C39: ACH - EMILIO STERLING LOVET WILSON | D39: 67 | E39: 30 | G39: =+G38+E39+F39 -> 5652.71 | K39: 4 | L39: 30 | M39: 17074
A40: 45752.1 | B40: 17089 | C40: YAPPY DE EDGAR PAUL ORTEGA PIMENTEL POR Mant Casa 323 Flia Ortega mayo y junio | D40: 323 | E40: 30 | G40: =+G39+E40+F40 -> 5682.71 | K40: 116 | L40: 15 | M40: 17075
A41: 45754.1 | B41: 17090 | C41: ACH - YARABY ORQUIDIA JIMENEZ JONES DE ABRAHAM | D41: 303 | E41: 45 | G41: =+G40+E41+F41 -> 5727.71 | K41: 294 | L41: 90 | M41: 17087
A42: 45754.1 | B42: 17091 | C42: ACH - PAMELA PATRICIA PETERS BAILEY\ belford | D42: 177 | E42: 45 | G42: =+G41+E42+F42 -> 5772.71 | K42: 57 | L42: 15 | M42: 17094
A43: 45751.1 | B43: 17092 | C43: YAPPY DE DAVID KERR RUDY MONTERO POR casa 32 mes Abril familia Rudy | D43: 32 | E43: 15 | G43: =+G42+E43+F43 -> 5787.71 | K43: 55 | L43: 45 | M43: 17096
A44: 45752.1 | B44: 17093 | C44: YAPPY DE MANUEL DE JESUS MEDINA ORTEGA | D44: 25 | E44: 30 | G44: =+G43+E44+F44 -> 5817.71 | K44: 334 | L44: 60 | M44: 17101
A45: 45753.1 | B45: 17095 | C45: BANCA MOVIL TRANSFERENCIA DE ALIZA EMERITA JIMENEZ | D45: 30 | E45: 15 | G45: =+G44+E45+F45 -> 5832.71 | K45: 318 | L45: 15 | M45: 17102
...

Sheet pagos mayo 2025
A1: DETALLE DE PAGOS EN BANCO
B2: MES DE MAYO DE 2025
A4: Cuenta:Alborada 04-11-00-000468-4
A8: Fecha | B8: Recibo | C8: Descripción | D8: No.Casa | E8: Cobros | F8: Pagos | G8: Saldo total
A10: 45777 | C10: SALDO AL 30 DE ABRIL DE 2025 | E10: =+'abril Saraliz'!G166 -> 7943.65 | G10: =+E10 -> 7943.65
A11: 45778.609 | B11: 17215 | C11: YAPPY DE JOSE DAVID BONILLA ALVARADO POR Casa D14 Bonilla Gonzalez Mes Abril 2025 Garita | D11: D-14 | E11: 15 | G11: =+G10+E11+F11 -> 7958.65 | H11: a
A12: 45778.609 | B12: 17216 | C12: YAPPY DE ANSELMO EMILIANO FORDE CHRISTOPHER POR Casa 5 1ra Oeste familia Forde | D12: 5 | E12: 15 | G12: =+G11+E12+F12 -> 7973.65 | H12: a
A13: 45778.609 | B13: 17217 | C13: YAPPY DE VANESSA VICTORIA PARNTHER LUZCANDO POR Mant mes de abril casa 75 familia Parnther | D13: 75 | E13: 15 | G13: =+G12+E13+F13 -> 7988.65 | H13: a
A14: 45778.609 | B14: 17218 | C14: BANCA EN LINEA TRANSFERENCIA DE MARCELA PAVIA de LAJON (TRANSPORTE LAJON) pago de segurida | D14: D-06 | E14: 45 | G14: =+G13+E14+F14 -> 8033.65 | H14: a
A15: 45778.609 | B15: 17219 | C15: YAPPY DE KASHMAH SHAMMETH CADOGAN de LEWIS | D15: 150 | E15: 15 | G15: =+G14+E15+F15 -> 8048.65 | H15: a
A16: 45778.609 | B16: 17220 | C16: YAPPY DE MIXIA LIBETH MURILLO AYARZA POR Francisca Ayarza | D16: D-04 | E16: 60 | G16: =+G15+E16+F16 -> 8108.65 | H16: a
A17: 45779.609 | B17: 17221 | C17: BANCA MOVIL TRANSFERENCIA DE LUIS ENRIQUE AMADOR MARTINEZ pago mensual Mayo | D17: 195 | E17: 15 | G17: =+G16+E17+F17 -> 8123.65 | H17: a
A18: 45779.609 | B18: 17222 | C18: YAPPY DE ORLANDO ENRIQUE ARGUELLES CUESTA POR Casa 313 mayo junio | D18: 313 | E18: 30 | G18: =+G17+E18+F18 -> 8153.65 | H18: a
A19: 45779.609 | B19: PAGOS | C19: BANCA MOVIL TRANSFERENCIA A 0338011480674 TIGER SECURITY COMPANY AND TRAINING CENTER, S.A. | F19: -1819 | G19: =+G18+E19+F19 -> 6334.65
A20: 45779.609 | B20: 17223 | C20: ACH - EMILIO STERLING LOVET WILSON | D20: 67 | E20: 15 | G20: =+G19+E20+F20 -> 6349.65 | H20: a
A21: 45779.609 | B21: 17224 | C21: YAPPY DE SARALIZ LORENA HUSBAND DE VELASQUEZ POR casa 117 flia Velasquez | D21: 117 | E21: 15 | G21: =+G20+E21+F21 -> 6364.65 | H21: a
A22: 45779.609 | B22: 17225 | C22: ACH - HAMILTON GONZALEZ IRIS ELIZABETH DE | D22: 111 | E22: 30 | G22: =+G21+E22+F22 -> 6394.65 | H22: a
A23: 45779.609 | B23: 17226 | C23: nelson casa 31 | D23: 310 | E23: 45 | G23: =+G22+E23+F23 -> 6439.65 | H23: a
A24: 45779.609 | B24: 17227 | C24: isaias tate casa 239 mes de abril | D24: 239 | E24: 15 | G24: =+G23+E24+F24 -> 6454.65 | H24: a
A25: 45779.609 | B25: 17228 | C25: YAPPY DE CIARA LUZ JIMENEZ CONCEPCION MANT. MAYO | D25: 16 | E25: 15 | G25: =+G24+E25+F25 -> 6469.65 | H25: a
A26: 45780 | B26: 17229 | C26: FLIA. CEREZO - ABRIL A JULIO/25 | D26: 253 | E26: 60 | G26: =+G25+E26+F26 -> 6529.65 | H26: a
A27: 45781 | B27: 17230 | C27: FLIA SAUNDERS - MAYO Y JUNIO | D27: 285 | E27: 30 | G27: =+G26+E27+F27 -> 6559.65 | H27: a
B28: 17231 | C28: PAGO SE HIZO EL 03-ABRIL-2025 | D28: 145 | E28: 0 | G28: =+G27+E28+F28 -> 6559.65 | H28: a
A29: 45780.299 | B29: 17232 | C29: FLIA. VIVERO - ENERO Y ABRIL | D29: 145 | E29: 30 | G29: =+G28+E29+F29 -> 6589.65 | H29: a
A30: 45781 | B30: 17233 | C30: FLIA - DE CASTRO - MANT. ABRIL/25 | D30: 246 | E30: 15 | G30: =+G29+E30+F30 -> 6604.65 | H30: a
A31: 45781 | B31: 17234 | C31: MARIBEL LAGUNA - MANT. JULIO Y AGOSTO/25 | D31: 294 | E31: 30 | G31: =+G30+E31+F31 -> 6634.65 | H31: a
A32: 45779.299 | B32: 17235 | C32: YAPPY DE YULIXA DEL CARMEN ESPADA de SIERRA POR Flia Sierra casa 110 marzo | D32: 110 | E32: 15 | G32: =+G31+E32+F32 -> 6649.65 | H32: a
A33: 45779.299 | B33: 17236 | C33: YAPPY DE YUMITZIE ANNELIS HARWOOD de CEDEÑO POR mes de abril Flia Cedeno casa 192 | D33: 192 | E33: 15 | G33: =+G32+E33+F33 -> 6664.65 | H33: a
A34: 45779.299 | B34: 17237 | C34: BANCA MOVIL TRANSFERENCIA DE DALIS YADIRA BANDINI MANT. MAYO AGUSTINE Pago de mantenimiento flia Band | D34: 178 | E34: 15 | G34: =+G33+E34+F34 -> 6679.65 | H34: a
A35: 45780.299 | B35: 17238 | C35: BANCA MOVIL TRANSFERENCIA DE NIDIA SILGADO LEON Casa 164 mayo | D35: 164 | E35: 15 | G35: =+G34+E35+F35 -> 6694.65 | H35: a
A36: 45780.299 | B36: 17239 | C36: YAPPY DE YANETH YAMILKA BADILLA PINEDA POR cuota mayo casa 157 | D36: 157 | E36: 15 | G36: =+G35+E36+F36 -> 6709.65 | H36: a
A37: 45780.299 | B37: 17240 | C37: BANCA MOVIL TRANSFERENCIA DE FERNANDO CHAVERRA PINEDA Fernando Chaverra casa 317 junio | D37: 317 | E37: 15 | G37: =+G36+E37+F37 -> 6724.65 | H37: a
A38: 45780.299 | B38: 17241 | C38: BANCA MOVIL TRANSFERENCIA DE DAIZA BRU TORRES A TERCEROS mayo y junio | D38: 143 | E38: 30 | G38: =+G37+E38+F38 -> 6754.65 | H38: a
A39: 45780.299 | B39: 17242 | C39: BANCA MOVIL TRANSFERENCIA DE LILIAN JAZMIN TUÑON DE TOULIER abril mayo | D39: 332 | E39: 30 | G39: =+G38+E39+F39 -> 6784.65 | H39: a
A40: 45780.299 | B40: 17243 | C40: YAPPY DE IDA CEMA JACKSON de VALENCIA-abril | D40: 270 | E40: 15 | G40: =+G39+E40+F40 -> 6799.65 | H40: a
... A43: 45781.299 | B43: 17246 | C43: YAPPY DE JAZMINA ITZEL VEGA de SMITH POR seguridad y mantenimiento casa 328 Flia Vega mayo Y JUNIIO | D43: 328 | E43: 30 | G43: =+G42+E43+F43 -> 6874.65 | H43: a
A44: 45781.299 | B44: PAGOS | C44: BANCA MOVIL TRANSFERENCIA A 0495996629370 SANTOS DIOMEDES ARAUZ MEDINA mantenimiento porto | F44: -85 | G44: =+G43+E44+F44 -> 6789.65
A45: 45781.299 | B45: 17247 | C45: YAPPY DE MANUEL DE JESUS MEDINA ORTEGA POR seguridad de mayo y junio | D45: 25 | E45: 30 | G45: =+G44+E45+F45 -> 6819.65 | H45: a
A46: 45782.299 | B46: 17248 | C46: YAPPY DE NAYRA DEL CARMEN RAMOS RAMOS (O) JERONIMO VALENTIN HERNANDEZ POR pago de segurida MAYO | D46: 54 | E46: 15 | G46: =+G45+E46+F46 -> 6834.65 | H46: a
A47: 45782.299 | B47: 17249 | C47: BANCA EN LINEA TRANSFERENCIA DE 0427120001653 DAYRA LUCILA CANALES de SWANSTON casa 240 ma | D47: 240 | E47: 30 | G47: =+G46+E47+F47 -> 6864.65 | H47: a
...

Sheet pagos junio 2025
A1: DETALLE DE PAGOS EN BANCO
B2: MES DE JUNIO DE 2025
A4: Cuenta:Alborada 04-11-00-000468-4
A8: Fecha | B8: Recibo | C8: Descripción | D8: No.Casa | E8: Cobros | F8: Pagos | G8: Saldo total
A10: 45808 | C10: SALDO AL 31 DE MAYO DE 2025 | E10: =+'pagos mayo 2025'!G183 -> 7117.91 | G10: =+E10 -> 7117.91
A11: 45809.388 | B11: PAGOS | C11: BANCA MOVIL TRANSFERENCIA A 0338011480674 TIGER SECURITY COMPANY AND TRAINING CENTER, S.A. | D11: PAGOS | F11: -1819 | G11: =+G10+E11+F11 -> 5298.91 | H11: a
A12: 45809.388 | B12: 17374 | C12: YAPPY DE MIOZOTIS DEL CARMEN OLMOS LARA casa 10 mes de junio | D12: 10 | E12: 15 | G12: =+G11+E12+F12 -> 5313.91 | H12: a
A13: 45809.388 | B13: 17375 | C13: BANCA MOVIL TRANSFERENCIA DE YOLANDA FORBES FERNANDEZ mes de mayo casa 155 | D13: 155 | E13: 15 | G13: =+G12+E13+F13 -> 5328.91 | H13: a
A14: 45809.388 | B14: 17376 | C14: YAPPY DE LISSETH HERMINIA DE LA ESPADA de DE NICOLO POR casa 194 mensualidad abril- mayo | D14: 194 | E14: 30 | G14: =+G13+E14+F14 -> 5358.91 | H14: a
A15: 45809.388 | B15: 17377 | C15: BANCA MOVIL TRANSFERENCIA DE VICENTE ROOK FRUTO Pago de marzo y abril Fla Rook casa 309 | D15: 309 | E15: 30 | G15: =+G14+E15+F15 -> 5388.91 | H15: a
A16: 45809.388 | B16: 17378 | C16: BANCA MOVIL TRANSFERENCIA DE CARLOS ERNESTO LAMBERT PEREA MES DE MAYO Y JUNIO | D16: 223 | E16: 30 | G16: =+G15+E16+F16 -> 5418.91 | H16: a
A17: 45810.356 | B17: 17379 | C17: BANCA MOVIL TRANSFERENCIA DE CARLOS ANTONIO MORAN MC COY Mant-mayo casa 251 | D17: 251 | E17: 15 | G17: =+G16+E17+F17 -> 5433.91 | H17: a
A18: 45809.388 | B18: 17380 | C18: YAPPY DE ANSELMO EMILIANO FORDE CHRISTOPHER mes de junio | D18: 5 | E18: 15 | G18: =+G17+E18+F18 -> 5448.91 | H18: a
A19: 45811 | B19: 17355 | C19: EFECTIVO- FLIA. MENDOZA - MES DE ABRIL Y MAYO CASA 244 | D19: 244 | E19: 30 | G19: =+G18+E19+F19 -> 5478.91 | H19: a
A20: 45810 | B20: 17381 | C20: EFECTIVO - SAADIA MACKENZI - CASA 263 MES DE ENERO A ABRIL | D20: 263 | E20: 60 | G20: =+G19+E20+F20 -> 5538.91 | H20: a
A21: 45810 | B21: 17382 | C21: EFECTIVO - FLIA. DEL VALLE - CASA 90 MANT. ENERO A ABRIL | D21: 90 | E21: 60 | G21: =+G20+E21+F21 -> 5598.91 | H21: a
A22: 45810.356 | B22: 17383 | C22: deposito- Raul Murdock casa 95 - mant. Mayo | D22: 95 | E22: 15 | G22: =+G21+E22+F22 -> 5613.91
A23: 45810.356 | B23: 17384 | C23: YAPPY DE GUILLERMO CHALHOUB RODRIGUEZ POR Mayo y Junio 2025 Casa 250 Alborada | D23: 250 | E23: 30 | G23: =+G22+E23+F23 -> 5643.91 | H23: a
A24: 45810.356 | B24: 17385 | C24: BANCA MOVIL TRANSFERENCIA DE HECTOR GABRIEL IBARGUEN MURILLO mes de mayo flia Ibarguen | D24: 21 | E24: 15 | G24: =+G23+E24+F24 -> 5658.91 | H24: a
A25: 45811.356 | B25: 17386 | C25: YAPPY DE NAYRA DEL CARMEN RAMOS RAMOmes de junio casa 54 | D25: 54 | E25: 15 | G25: =+G24+E25+F25 -> 5673.91 | H25: a
A26: 45811.356 | B26: 17387 | C26: BANCA MOVIL TRANSFERENCIA DE LUIS ENRIQUE AMADOR MARTINEZ pago consergeria mes Junio | D26: 195 | E26: 15 | G26: =+G25+E26+F26 -> 5688.91 | H26: a
A27: 45811.466 | B27: 17388 | C27: YAPPY DE MANUEL ENRIQUE VILLARREAL GUILLEN -MES ABRIL Y MAYO | D27: 103 | E27: 30 | G27: =+G26+E27+F27 -> 5718.91 | H27: a
A28: 45811.466 | B28: 17389 | C28: YAPPY DE MANUEL ENRIQUE VILLARREAL GUILLEN -MES JUNIO | D28: 103 | E28: 15 | G28: =+G27+E28+F28 -> 5733.91 | H28: a
A29: 45811.466 | B29: 17390 | C29: BANCA MOVIL TRANSFERENCIA DE JESSENIA MAGALI FRUTO DE BETHANCOURT casa 112 Flia Bethancour | D29: 112 | E29: 45 | G29: =+G28+E29+F29 -> 5778.91 | H29: a
A30: 45811.466 | B30: 17391 | C30: YAPPY DE IDA CEMA JACKSON de VALENCIA - MAYO | D30: 270 | E30: 15 | G30: =+G29+E30+F30 -> 5793.91 | H30: a
A31: 45812.466 | B31: 17392 | C31: YAPPY DE PORFIRIO JUSTAVINO CEDEÑO casa 289 MES DE JUNIO | D31: 289 | E31: 15 | G31: =+G30+E31+F31 -> 5808.91 | H31: a
A32: 45812.466 | B32: 17393 | C32: YAPPY DE JACQUELINE YOVANIA VILLAMIL TORRES casa 298 - mayo | D32: 298 | E32: 15 | G32: =+G31+E32+F32 -> 5823.91 | H32: a
A33: 45812.466 | B33: 17394 | C33: BANCA MOVIL TRANSFERENCIA DE ISABEL RIQUELME MARTINEZ mensualidad junio casa 277 flia Riquelme | D33: 277 | E33: 15 | G33: =+G32+E33+F33 -> 5838.91 | H33: a
A34: 45812.466 | B34: 17395 | C34: BANCA MOVIL TRANSFERENCIA DE MARLENE BOYCE DAWKINS Garita 181 Abril | D34: 181 | E34: 15 | G34: =+G33+E34+F34 -> 5853.91 | H34: a
... A53: 45815.319 | B53: 17414 | C53: YAPPY DE YOLANDA ENEIDA LOPER ALABARCA POR mantenimiento junio 2025 casa 271 | D53: 271 | E53: 20 | G53: =+G52+E53+F53 -> 6328.91 | H53: a
A54: 45815.319 | B54: 17415 | C54: BANCA MOVIL TRANSFERENCIA DE DALIA ZORAIDA PETERS PAYNE Familia Peters casa 121 y 104 abriL Y MAYO | D54: 121 Y 104 | E54: 60 | G54: =+G53+E54+F54 -> 6388.91 | H54: a
A55: 45815.319 | B55: PAGOS | C55: BANCA MOVIL TRANSFERENCIA A 0472996299559 PEDRO ANTONIO GLASGOW BARRETT corte de hierba | D55: PAGOS | F55: -150 | G55: =+G54+E55+F55 -> 6238.91 | H55: a
A56: 45815.319 | B56: 17416 | C56: BANCA MOVIL TRANSFERENCIA DE FERNANDO CHAVERRA PINEDA Fernando Chaverra 3 86 1038 casa 317 MES DE JULIO | D56: 317 | E56: 15 | G56: =+G55+E56+F56 -> 6253.91 | H56: a
A57: 45815.319 | B57: PAGOS | C57: YAPPY A RODERICK ANEL CHIRU VALDES POR CIRTE HIERBA PARQUE 6TA OESTE PEQ Y CENTRO Y VEREDA | D57: PAGOS | F57: -188 | G57: =+G56+E57+F57 -> 6065.91 | H57: a
A58: 45815.319 | B58: PAGOS | C58: YAPPY A MIGUEL ROGELIO SANCHEZ PALACIO POR Bolsas de Basura corte hierba Alborada | D58: PAGOS | F58: -12.38 | G58: =+G57+E58+F58 -> 6053.53 | H58: a
A59: 45815.319 | B59: PAGOS | C59: YAPPY A RODERICK ANEL CHIRU VALDES POR Excedentes corte hierba | D59: PAGOS | F59: -22 | G59: =+G58+E59+F59 -> 6031.53 | H59: a
A60: 45815.319 | B60: 17417 | C60: BANCA MOVIL TRANSFERENCIA DE YOLANDA MAGALI CAMPOS GONZALEZ seguridad y mant junio 2025 | D60: 304 | E60: 15 | G60: =+G59+E60+F60 -> 6046.53 | H60: a
A61: 45816.319 | B61: 17418 | C61: YAPPY DE CIARA LUZ JIMENEZ CONCEPCION - MES JUNIO Y JULIO | D61: 16 | E61: 30 | G61: =+G60+E61+F61 -> 6076.53 | H61: a
A62: 45816.319 | B62: 17419 | C62: BANCA MOVIL TRANSFERENCIA DE DALIS YADIRA BANDINI AGUSTINE Pago MES DE JULIO seguridad flia Bandini Cha | D62: 178 | E62: 15 | G62: =+G61+E62+F62 -> 6091.53 | H62: a
A63: 45817.319 | B63: PAGOS | C63: YAPPY A MELVIN CARLTON FOSTER GALASTICA POR PODA PARQUES 3A Y CUARTA CENTRO | D63: PAGOS | F63: -60 | G63: =+G62+E63+F63 -> 6031.53 | H63: a
...

Sheet pagos julio 2025
A1: DETALLE DE PAGOS EN BANCO
A2: MES DE JULIO DE 2025
A4: Cuenta:Alborada 04-11-00-000468-4
A8: Fecha | B8: Recibo | C8: Descripción | D8: No.Casa | E8: Cobros | F8: Pagos | G8: Saldo total
A10: 45838 | C10: SALDO AL 30 DE JUNIO DE 2025 | E10: =+'pagos junio 2025'!G158 -> 4424.69 | G10: =+E10 -> 4424.69
A11: 45843 | B11: 17474 | C11: Efectivo - casa 306 Roberto Jenkins - mes de Junio | D11: 306 | E11: 15 | G11: =+G10+E11+F11 -> 4439.69
A12: 45839 | B12: 17504 | C12: YAPPY BG DE MIOZOTIS DEL CARMEN OLMOS LARA- MES DE JULIO | D12: 10 | E12: 15 | G12: =+G11+E12+F12 -> 4454.69 | H12: a
A13: 45839 | B13: 17505 | C13: BANCA MOVIL TRANSFERENCIA DE BARBARA ANN BENDIGO DE SANTAMARIA Agosto 2025 Flia Santamaria | D13: 44 | E13: 15 | G13: =+G12+E13+F13 -> 4469.69 | H13: a
A14: 45839 | B14: 17506 | C14: YAPPY BG DE JACQUELINE YOVANIA VILLAMIL TORRES- MES DE JUNIO | D14: 298 | E14: 15 | G14: =+G13+E14+F14 -> 4484.69 | H14: a
A15: 45839 | B15: 17507 | C15: BANCA MOVIL TRANSFERENCIA DE FERNANDO JOSE PENAS BLANCO (O) FERNANDO ANTONIO PENAS DOMING MES DE MAYO | D15: 169 | E15: 15 | G15: =+G14+E15+F15 -> 4499.69 | H15: a
A16: 45839 | B16: 17508 | C16: YAPPY BG DE NAYRA DEL CARMEN RAMOS RAMOS (O) JERONIMO VALENTIN HERNANDEZ POR pago de Segu- JULIO | D16: 54 | E16: 15 | G16: =+G15+E16+F16 -> 4514.69 | H16: a
A17: 45839 | B17: 17509 | C17: BANCA MOVIL TRANSFERENCIA DE CELIA ESTHER SALAZAR de PAULT casa 183 mes de abril y mayo | D17: 183 | E17: 30 | G17: =+G16+E17+F17 -> 4544.69 | H17: a
A18: 45839 | B18: 17510 | C18: BANCA MOVIL TRANSFERENCIA DE ORLANDO ENRIQUE ARGUELLES CUESTA Julio Agosto casa 313 | D18: 313 | E18: 30 | G18: =+G17+E18+F18 -> 4574.69 | H18: a
A19: 45839 | B19: 17511 | C19: YAPPY BG DE YARITZA YAMILKA COOPER CHIFUNDO POR Casa 202 SChifundo YCooper mes de Junio 2 | D19: 202 | E19: 15 | G19: =+G18+E19+F19 -> 4589.69 | H19: a
A20: 45840 | B20: 17512 | C20: YAPPY BG DE MARIET BROOKS SALAMANCA POR seguridad flia Brooks- MAYO Y JUNIO | D20: 78 | E20: 30 | G20: =+G19+E20+F20 -> 4619.69 | H20: a
A21: 45840 | B21: 17513 | C21: YAPPY BG DE NELSON AZARIAS MORENO MAGDALENO POR Casa 310 mes de junio | D21: 310 | E21: 15 | G21: =+G20+E21+F21 -> 4634.69 | H21: a
A22: 45840 | B22: 17514 | C22: DEPOSITO -RAUL MURDOCK - JUNIO | D22: 95 | E22: 15 | G22: =+G21+E22+F22 -> 4649.69 | H22: a
A23: 45840 | B23: 17515 | C23: YAPPY BG DE LINETH GISSEL SANTOS MELENDEZ POR abril mayo junio Familia Paz casa 7 | D23: 7 | E23: 45 | G23: =+G22+E23+F23 -> 4694.69 | H23: a
... A34: 45841 | B34: 17526 | C34: ACH - GEORGIANA GAVIRIA PACHECO- JUNIO Y JULIO | D34: 86 | E34: 30 | G34: =+G33+E34+F34 -> 4989.69 | H34: a
A35: 45841 | B35: PAGOS | C35: BANCA MOVIL TRANSFERENCIA A 0427998627468 CHINA PANDA LIGHTS, S.A. lamparas garita | D35: PAGOS | E35: 0 | F35: -41.2 | G35: =+G34+E35+F35 -> 4948.49 | H35: a
A36: 45841 | B36: PAGOS | C36: BANCA MOVIL GLOBAL BANK 23332000633 Enrique Silvera | D36: PAGOS | E36: 0 | F36: -100 | G36: =+G35+E36+F36 -> 4848.49 | H36: a
A37: 45841 | B37: 17527 | C37: YAPPY BG DE SHANI NG de CHIU POR Familia Chiu pago de junio 2025 | D37: 292 | E37: 15 | G37: =+G36+E37+F37 -> 4863.49 | H37: a
A38: 45841 | B38: PAGOS | C38: BANCA MOVIL TRANSFERENCIA A 0454000010658 JOSE ALBERTO MARCIAGA BRAVO pintar y reparar por | D38: PAGOS | E38: 0 | F38: -100 | G38: =+G37+E38+F38 -> 4763.49 | H38: a
A39: 45842 | B39: 17528 | C39: BANCA MOVIL TRANSFERENCIA DE NIDIA SILGADO LEON Casa 164- JULIO | D39: 164 | E39: 15 | G39: =+G38+E39+F39 -> 4778.49 | H39: a
A40: 45842 | B40: 17529 | C40: YAPPY BG DE MANUEL DE JESUS MEDINA ORTEGA POR casa25 mensualidad julio y agosto | D40: 25 | E40: 30 | G40: =+G39+E40+F40 -> 4808.49 | H40: a
A41: 45842 | B41: 17530 | C41: BANCA MOVIL TRANSFERENCIA DE ADA ARGELIA CHONG CORREA - ABRIL Y MAYO | D41: 133 | E41: 30 | G41: =+G40+E41+F41 -> 4838.49 | H41: a
A42: 45843 | B42: 17531 | C42: YAPPY BG DE ANA MICHELLE PILE OSSA (O) ARELIS VANESSA OSSA DIAZ POR junio casa 106 AOssa | D42: 106 | E42: 15 | G42: =+G41+E42+F42 -> 4853.49 | H42: a
A43: 45843 | B43: 17532 | C43: YAPPY BG DE YULIXA DEL CARMEN ESPADA de SIERRA POR Casa 110 Flia Sierra Espada - MAYO | D43: 110 | E43: 15 | G43: =+G42+E43+F43 -> 4868.49 | H43: a
A44: 45843 | B44: 17533 | C44: YAPPY BG DE YOLANDA ENEIDA LOPER ALABARCA POR mantenimiento julio 25 casa 271 | D44: 271 | E44: 20 | G44: =+G43+E44+F44 -> 4888.49 | H44: a
A45: 45843 | B45: 17534 | C45: YAPPY BG DE LUZMILA ELENA PORTER DE QUINTERO POR 050625 LUZMILA PORTER PRIMERA C47 - JUNIO | D45: 47 | E45: 15 | G45: =+G44+E45+F45 -> 4903.49 | H45: a
A46: 45843 | B46: 17535 | C46: BANCA MOVIL TRANSFERENCIA DE FERNANDO CHAVERRA PINEDA Fernando Chaverra casa 317- AGOSTO | D46: 317 | E46: 15 | G46: =+G45+E46+F46 -> 4918.49 | H46: a
A47: 45843 | B47: 17536 | C47: YAPPY BG DE STEPHANIE MICHELLE ESPINOSA GONZALEZ POR Casa 123 flia Espinosa mes de junio- JULIO Y AGOSTO | D47: 123 | E47: 45 | G47: =+G46+E47+F47 -> 4963.49 | H47: a
A48: 45843 | B48: PAGOS | C48: YAPPY BG A RODERICK ANEL CHIRU VALDES POR Parques 6ta vereda Circunvalacion | D48: PAGOS | E48: 0 | F48: -210 | G48: =+G47+E48+F48 -> 4753.49 | H48: a
A49: 45843 | B49: PAGOS | C49: BANCA MOVIL GLOBAL BANK 23332000633 Enrique Silvera | D49: PAGOS | E49: 0 | F49: -400 | G49: =+G48+E49+F49 -> 4353.49 | H49: a
A50: 45843 | B50: PAGOS | C50: BANCA MOVIL TRANSFERENCIA A 0495996629370 SANTOS DIOMEDES ARAUZ MEDINA puerta peatonal | D50: PAGOS | E50: 0 | F50: -385.8 | G50: =+G49+E50+F50 -> 3967.69 | H50: a
A51: 45843 | B51: PAGOS | C51: BANCA MOVIL TRANSFERENCIA A 0472996299559 PEDRO ANTONIO GLASGOW BARRETT corte de hierba | D51: PAGOS | E51: 0 | F51: -150 | G51: =+G50+E51+F51 -> 3817.69 | H51: a
A52: 45843 | B52: 17537 | C52: YAPPY BG DE YANETH YAMILKA BADILLA PINEDA POR cuota julio casa 157 | D52: 157 | E52: 15 | G52: =+G51+E52+F52 -> 3832.69 | H52: a
A53: 45843 | B53: PAGOS | C53: YAPPY BG A MIGUEL ROGELIO SANCHEZ PALACIO POR Insumos corte hierba Alborada | D53: PAGOS | E53: 0 | F53: -23.57 | G53: =+G52+E53+F53 -> 3809.12 | H53: a
A54: 45843 | B54: 17538 | C54: YAPPY BG DE DIANA MARIA SANCHEZ FLORES - FLIA VEGA - JUNIO | D54: D-24 | E54: 15 | G54: =+G53+E54+F54 -> 3824.12 | H54: a
A55: 45844 | B55: 17539 | C55: YAPPY BG DE JAIME ALBERTO PEREZ MERO- JULIO 205 | D55: 205 | E55: 15 | G55: =+G54+E55+F55 -> 3839.12 | H55: a
...

Sheet pagos agosto 2025
A1: DETALLE DE PAGOS EN BANCO
A2: MES DE AGOSTO DE 2025
A4: Cuenta:Alborada 04-11-00-000468-4
A8: Fecha | B8: Recibo | C8: Descripción | D8: No.Casa | E8: Cobros | F8: Pagos | G8: Saldo total
A10: 45869 | C10: SALDO AL 31 DE JULIO DE 2025 | G10: =+'pagos julio 2025'!G172 -> 4235.22
A11: 45870 | B11: 17640 | C11: YAPPY BG DE YARITZA YAMILKA COOPER CHIFUNDO POR Mes de Julio 2025 Casa 202 SChifundo YCoo | D11: 202 | E11: 15 | G11: =+G10+E11+F11 -> 4250.22 | H11: a
A12: 45870 | B12: 17641 | C12: YAPPY BG DE QUERUBI LIZET NEREIDA de HILTON POR Pago mes de JuNIO Y JULIO | D12: 19 | E12: 30 | G12: =+G11+E12+F12 -> 4280.22 | H12: a
A13: 45870 | B13: 17642 | C13: BANCA MOVIL TRANSFERENCIA DE FERNANDO JOSE PENAS BLANCO (O) FERNANDO ANTONIO PENAS DOMING - JUNIO | D13: 169 | E13: 15 | G13: =+G12+E13+F13 -> 4295.22 | H13: a
A14: 45870 | B14: 17643 | C14: BANCA MOVIL TRANSFERENCIA DE FERNANDO CHAVERRA PINEDA Fernando Chaverra casa 317 OCTUBRE | D14: 317 | E14: 15 | G14: =+G13+E14+F14 -> 4310.22 | H14: a
A15: 45870 | B15: 17644 | C15: DEPOSITO - FLIA SMALL- MAYO Y JUNIO | D15: 39 | E15: 30 | G15: =+G14+E15+F15 -> 4340.22 | H15: a
A16: 45870 | B16: 17645 | C16: YAPPY BG DE ANA MICHELLE PILE OSSA (O) ARELIS VANESSA OSSA DIAZ POR casa 106-Arelis Ossa- MES DE JULIO | D16: 106 | E16: 15 | G16: =+G15+E16+F16 -> 4355.22 | H16: a
A17: 45870 | B17: PAGOS | C17: BANCA EN LINEA TRANSFERENCIA A 0338011480674 TIGER SECURITY COMPANY AND TRAINING CENTER, S | D17: PAGOS | E17: 0 | F17: -1819 | G17: =+G16+E17+F17 -> 2536.22 | H17: a
A18: 45874 | B18: 17646 | C18: EFECTIVO - PIEDAD DEL CID - MANT. -AGOSTO | D18: 57 | E18: 15 | G18: =+G17+E18+F18 -> 2551.22 | H18: a
A19: 45874 | B19: 17647 | C19: EFECTIVO - ALBERTO BENETT - MANT- MAYO, JUNIO Y JULIO | D19: 55 | E19: 45 | G19: =+G18+E19+F19 -> 2596.22 | H19: a
A20: 45877 | B20: 17648 | C20: EFECTIVO - OFELIA MITCHELL- MANT- JUNIO, JULIO Y AGOSTO | D20: 260 | E20: 45 | G20: =+G19+E20+F20 -> 2641.22 | H20: a
A21: 45877 | B21: 17649 | C21: EFECTIVO - PABLO MEJIA - MENS- JULIO A DICIEMBRE | D21: 50 | E21: 90 | G21: =+G20+E21+F21 -> 2731.22 | H21: a
A22: 45881 | B22: 17650 | C22: EFECTIVO - FLIA GUERRA - SALAZAR - MENS-ENERO A JULIO | D22: 255 | E22: 105 | G22: =+G21+E22+F22 -> 2836.22 | H22: a
A23: 45876 | B23: 17651 | C23: EFECTIVO - FLIA NORSE - MENS- MAYO, JUNIO Y JULIO | D23: 318 | E23: 45 | G23: =+G22+E23+F23 -> 2881.22 | H23: a
A24: 45877 | B24: 17652 | C24: YAPPY - CARLOS GARAY - MANT- AGOSTO | D24: 4 | E24: 15 | G24: =+G23+E24+F24 -> 2896.22 | H24: a
A25: 45876 | B25: 17653 | C25: YAPPY - Hector Ibarguen- MANT- JULIO | D25: 21 | E25: 15 | G25: =+G24+E25+F25 -> 2911.22 | H25: a
A26: 45870 | B26: 17654 | C26: BANCA MOVIL TRANSFERENCIA DE LILIAN JAZMIN TUÑON DE TOULIER Junio Julio 332 | D26: 332 | E26: 30 | G26: =+G25+E26+F26 -> 2941.22 | H26: a
A27: 45870 | B27: 17655 | C27: YAPPY BG DE YUMITZIE ANNELIS HARWOOD de CEDEÑO POR mes de julio Flia Cedeno casa 192 | D27: 192 | E27: 15 | G27: =+G26+E27+F27 -> 2956.22 | H27: a
A28: 45870 | B28: 17656 | C28: BANCA MOVIL TRANSFERENCIA DE MARCELA PAVIA de LAJON -julio, agosto y septiembre | D28: D-6 | E28: 45 | G28: =+G27+E28+F28 -> 3001.22 | H28: a
A29: 45870 | B29: PAGOS | C29: BANCA MOVIL TRANSFERENCIA A 0403014310197 DAGOBERTO DAVID PARIS ARIAS REGISTRO PUBLICO ALB | D29: PAGOS | E29: 0 | F29: -30 | G29: =+G28+E29+F29 -> 2971.22 | H29: a
A30: 45870 | B30: 17657 | C30: BANCA MOVIL TRANSFERENCIA DE ROSEMENE SERVILIUS MEDIEU- MES DE FEBRERO,MARZO Y ABRIL | D30: 182 | E30: 45 | G30: =+G29+E30+F30 -> 3016.22 | H30: a
A31: 45870 | B31: 17658 | C31: YAPPY BG DE WYLMA ISUALY MATURANA DE ESCOBAR- junio | D31: 85 | E31: 15 | G31: =+G30+E31+F31 -> 3031.22 | H31: a
A32: 45870 | B32: 17659 | C32: YAPPY BG DE LUCAS ANTONIO CORTES SURGEON POR Pago julio agosto casa 134 | D32: 134 | E32: 30 | G32: =+G31+E32+F32 -> 3061.22 | H32: a
A33: 45870 | B33: 17660 | C33: YAPPY BG DE ANSELMO EMILIANO FORDE CHRISTOPHER mes de agosto | D33: 5 | E33: 15 | G33: =+G32+E33+F33 -> 3076.22 | H33: a
A34: 45870 | B34: 17661 | C34: BANCA MOVIL TRANSFERENCIA DE ADA ARGELIA CHONG CORREA junio y julio | D34: 133 | E34: 30 | G34: =+G33+E34+F34 -> 3106.22 | H34: a
A35: 45870 | B35: 17662 | C35: YAPPY BG DE PORFIRIO JUSTAVINO CEDEÑO POR mes de agosto 289 | D35: 289 | E35: 15 | G35: =+G34+E35+F35 -> 3121.22 | H35: a
A36: 45870 | B36: 17663 | C36: BANCA MOVIL TRANSFERENCIA DE DALIS YADIRA BANDINI AGUSTINE Pago seguridad Flia Bandini - SEPTIEMBRE Y OCTUBRE | D36: 178 | E36: 30 | G36: =+G35+E36+F36 -> 3151.22 | H36: a
A37: 45870 | B37: 17664 | C37: YAPPY BG DE YULIXA DEL CARMEN ESPADA de SIERRA POR Casa 110 - JUNIO | D37: 110 | E37: 15 | G37: =+G36+E37+F37 -> 3166.22 | H37: a
A38: 45870 | B38: 17665 | C38: BANCA MOVIL TRANSFERENCIA DE LUIS ENRIQUE AMADOR MARTINEZ pago del mes de agosto | D38: 195 | E38: 15 | G38: =+G37+E38+F38 -> 3181.22 | H38: a
A39: 45871 | B39: 17666 | C39: BANCA EN LINEA TRANSFERENCIA DE DALIA ZORAIDA PETERS PAYNE Familia Peters casa 121 y 104 - mes de agosto | D39: 121 Y 104 | E39: 30 | G39: =+G38+E39+F39 -> 3211.22 | H39: a
A40: 45871 | B40: 17667 | C40: YAPPY BG DE NIDIA ROSA BOHORQUEZ de MARTINEZ POR pago 2 meses julio y agosto familia mart | D40: 63 | E40: 30 | G40: =+G39+E40+F40 -> 3241.22 | H40: a
A41: 45871 | B41: 17668 | C41: YAPPY BG DE JACQUELINE YOVANIA VILLAMIL TORRES- MES DE JULIO | D41: 298 | E41: 15 | G41: =+G40+E41+F41 -> 3256.22 | H41: a
A42: 45871 | B42: 17669 | C42: YAPPY BG DE JAIME DAVID ANDERSON SINCLAIR - mes de julio | D42: 172 | E42: 15 | G42: =+G41+E42+F42 -> 3271.22 | H42: a
A43: 45871 | B43: 17670 | C43: YAPPY BG DE JOSE DAVID BONILLA ALVARADO POR Garita Julio 2025 D14 Familia Bonilla | D43: D14 | E43: 15 | G43: =+G42+E43+F43 -> 3286.22 | H43: a
A44: 45871 | B44: PAGOS | C44: BANCA MOVIL TRANSFERENCIA A 0472996299559 PEDRO ANTONIO GLASGOW BARRETT corte de hierba de | D44: PAGOS | E44: 0 | F44: -150 | G44: =+G43+E44+F44 -> 3136.22 | H44: a
A45: 45871 | B45: PAGOS | C45: YAPPY BG A RODERICK ANEL CHIRU VALDES POR CORTE PARQUES SEXTA Y VEREDA CIRCUNVALACION | D45: PAGOS | E45: 0 | F45: -210 | G45: =+G44+E45+F45 -> 2926.22 | H45: a
...

Sheet pagos septiembre 2025
A1: DETALLE DE PAGOS EN BANCO
A2: MES DE SEPTIEMBRE DE 2025
A4: Cuenta:Alborada 04-11-00-000468-4
A8: Fecha | B8: Recibo | C8: Descripción | D8: No.Casa | E8: Cobros | F8: Pagos | G8: Saldo total
A10: 45900 | C10: SALDO AL 31 DE AGOSTO DE 2025 | G10: =+'pagos agosto 2025'!G223 -> 3835.26 | H10: a
A11: 45903 | B11: 17773 | C11: ACH XPRESS - DENNIS BARNES GRAHAM- SEPTIEMBRE Y OCTUBRE | D11: 148 | E11: 30 | G11: =+G10+E11+F11 -> 3865.26 | H11: a
A12: 45907 | B12: 17774 | C12: EFECTIVO - CARLOS LEOTEAU - MES DE SEPIEMBRE A DICIEMBRE | D12: 281 | E12: 60 | G12: =+G11+E12+F12 -> 3925.26 | H12: a
A13: 45901 | B13: 17794 | C13: DEPOSITO FLIA TACHAR - JULIO, AGOSTO Y SEPTIEMBRE | D13: 15 | E13: 45 | G13: =+G12+E13+F13 -> 3970.26 | H13: a
A14: 45901 | B14: RIFA | C14: BANCA EN LINEA TRANSFERENCIA DE 0427120001653 DAYRA LUCILA CANALES de SWANSTON rifa darish | D14: RIFA | E14: 10 | G14: =+G13+E14+F14 -> 3980.26 | H14: a
A15: 45901 | B15: RIFA | C15: BANCA EN LINEA TRANSFERENCIA DE 0427120001653 DAYRA LUCILA CANALES de SWANSTON rifa | D15: RIFA | E15: 40 | G15: =+G14+E15+F15 -> 4020.26 | H15: a
A16: 45901 | B16: RIFA | C16: ACH XPRESS - JOSE LUIS GONZALEZ FLETCHER O MAIQUEL ITZELA POLLACK | D16: RIFA | E16: 10 | G16: =+G15+E16+F16 -> 4030.26 | H16: a
A17: 45901 | B17: RIFA | C17: BANCA MOVIL TRANSFERENCIA DE YENITZA NAYROBIS ASHAW SMALL | D17: RIFA | E17: 10 | G17: =+G16+E17+F17 -> 4040.26 | H17: a
A18: 45901 | B18: 17795 | C18: YAPPY BG DE YARITZA YAMILKA COOPER CHIFUNDO POR Mes de agosto 2025 Casa 202 Silvina Chifu | D18: 202 | E18: 15 | G18: =+G17+E18+F18 -> 4055.26 | H18: a
A19: 45901 | B19: 17796 | C19: YAPPY BG DE MARIA DE LOS ANGELES MONTENEGRO DE LEON POR pago a casa 14 familia montenegro - AGOSTO Y SEPTIEMBRE | D19: 14 | E19: 30 | G19: =+G18+E19+F19 -> 4085.26 | H19: a
A20: 45901 | B20: 17797 | C20: BANCA MOVIL TRANSFERENCIA DE GISELA GONZALEZ QUIROZ Casa 88 GISELA GONZALEZ Seg AGOSTO A DICIEMBRE | D20: 88 | E20: 75 | G20: =+G19+E20+F20 -> 4160.26 | H20: a
A21: 45901 | B21: 17798 | C21: BANCA MOVIL TRANSFERENCIA DE MIGUEL ROGELIO SANCHEZ - MES DE AGOSTO Y SEPTIEMBRE | D21: 6 | E21: 30 | G21: =+G20+E21+F21 -> 4190.26 | H21: a
A22: 45901 | B22: PAGOS | C22: BANCA MOVIL TRANSFERENCIA A 0338011480674 TIGER SECURITY COMPANY AND TRAINING CENTER, S.A. | D22: PAGOS | E22: 0 | F22: -1819 | G22: =+G21+E22+F22 -> 2371.26 | H22: a
A23: 45901 | B23: 17799 | C23: YAPPY BG DE YULIXA DEL CARMEN ESPADA de SIERRA POR Casa 110 Flia Sierra MES DE JULIO | D23: 110 | E23: 15 | G23: =+G22+E23+F23 -> 2386.26 | H23: a
A24: 45901 | B24: RIFA | C24: YAPPY BG DE EMMANUEL ESTEBAN CABRERA MARTINEZ | D24: RIFA | E24: 10 | G24: =+G23+E24+F24 -> 2396.26 | H24: a
A25: 45903 | B25: 17800 | C25: EFECTIVO - LUIS LEVIS - MES DE MARZO Y ABRIL | D25: 234 | E25: 30 | G25: =+G24+E25+F25 -> 2426.26 | H25: a
A26: 45902 | B26: 17801 | C26: EFECTIVO - FLIA MENDOZA - SEPTIEMBRE Y OCTUBRE CASA 244 | D26: 244 | E26: 30 | G26: =+G25+E26+F26 -> 2456.26 | H26: a
A27: 45904 | B27: 17802 | C27: EFECTIVO - JAZMIN MENDOZA - MARZO $5 Y ABRIL $5 | D27: 170 | E27: 10 | G27: =+G26+E27+F27 -> 2466.26 | H27: a
A28: 45906 | B28: 17803 | C28: EFECTIVO - FLIA CUERO - AGOSTO Y SEPTIEMBRE - CASA 253 | D28: 253 | E28: 30 | G28: =+G27+E28+F28 -> 2496.26 | H28: a
A29: 45907 | B29: 17804 | C29: EFECTIVO - DELANO SAUNDERS - MAT. SEPTIEMBRE Y OCTUBRE | D29: 285 | E29: 30 | G29: =+G28+E29+F29 -> 2526.26 | H29: a
A30: 45907 | B30: 17805 | C30: EFECTIVO - PIEDAD DEL CID - MANT-SEPTIEMBRE -CASA 57 | D30: 57 | E30: 15 | G30: =+G29+E30+F30 -> 2541.26 | H30: a
A31: 45907 | B31: 17806 | C31: ACH XPRESS - PAMELA PATRICIA PETERS BAILEY OR ALBERTO BELFORD MEL | D31: 177 | E31: 45 | G31: =+G30+E31+F31 -> 2586.26 | H31: a
A32: 45905 | B32: 17807 | C32: ACH - GEORGIANA GAVIRIA PACHECO - mes de agosto y septiembre | D32: 86 | E32: 30 | G32: =+G31+E32+F32 -> 2616.26 | H32: a
A33: 45907 | B33: TARJETA | C33: ACH- EXPRESS - ALBERTO BELFORD - CASA 177- TARJETA | D33: TARJETA | E33: 10 | G33: =+G32+E33+F33 -> 2626.26 | H33: a
A34: 45907 | B34: 17808 | C34: EFECTIVO - FLIA DEL VALLE - MAYO A SEPTIEMBRE - CASA 90 | D34: 90 | E34: 75 | G34: =+G33+E34+F34 -> 2701.26 | H34: a
A35: 45907 | B35: 17809 | C35: EFECTIVO - KAREN GONZALEZ - MANT. ABRIL A SEPTIEMBRE | D35: 97 | E35: 90 | G35: =+G34+E35+F35 -> 2791.26 | H35: a
A36: 45907 | B36: 17810 | C36: EFECTIVO - IRACEMA DE SMALL- MES DE JULIO | D36: 119 | E36: 15 | G36: =+G35+E36+F36 -> 2806.26 | H36: a
A37: 45902 | B37: 17811 | C37: ACH XPRESS - DEMETRIO CELSO PRESCOTT RODRIGUEZ - AGOSTO Y SEPTIEMBRE | D37: 241 | E37: 30 | G37: =+G36+E37+F37 -> 2836.26 | H37: a
A38: 45907 | B38: 17812 | C38: EFECTIVO - FLIA HALL - MES DE ENERO A AGOSTO | D38: 197 | E38: 120 | G38: =+G37+E38+F38 -> 2956.26 | H38: a
A39: 45901 | B39: RIFA | C39: YAPPY BG DE NATALIA KATIUSKA WARDROPE SANCHEZ | D39: RIFA | E39: 40 | G39: =+G38+E39+F39 -> 2996.26 | H39: a
A40: 45901 | B40: TARJETA | C40: YAPPY BG DE YUMITZIE ANNELIS HARWOOD de CEDEÑO POR tarjeta casa 192 Flia Cedeno | D40: TARJETA | E40: 10 | G40: =+G39+E40+F40 -> 3006.26 | H40: a
A41: 45901 | B41: 17815 | C41: BANCA MOVIL TRANSFERENCIA DE JESSENIA MAGALI FRUTO DE BETHANCOURT casa 112 Bethancourt - JULIO, AGOSTO Y SEPTIEMBRE | D41: 112 | E41: 45 | G41: =+G40+E41+F41 -> 3051.26 | H41: a
A42: 45902 | B42: 17816 | C42: BANCA EN LINEA TRANSFERENCIA DE 0427120001653 DAYRA LUCILA CANALES de SWANSTON mes de septIEMBRE Y OCTUBRE | D42: 240 | E42: 30 | G42: =+G41+E42+F42 -> 3081.26 | H42: a
A43: 45902 | B43: RIFA | C43: BANCA EN LINEA TRANSFERENCIA DE 0427120001653 DAYRA LUCILA CANALES de SWANSTON rifa efecti | D43: RIFA | E43: 100 | G43: =+G42+E43+F43 -> 3181.26 | H43: a
A44: 45902 | B44: 17817 | C44: BANCA MOVIL TRANSFERENCIA DE FERNANDO JOSE PENAS BLANCO (O) FERNANDO ANTONIO PENAS DOMING- MES DE JULIO | D44: 169 | E44: 15 | G44: =+G43+E44+F44 -> 3196.26 | H44: a
A45: 45902 | B45: 17818 | C45: YAPPY BG DE NURIA ELENA JIMENEZ de ABREGO POR casa 193 - MAYO | D45: 193 | E45: 15 | G45: =+G44+E45+F45 -> 3211.26 | H45: a
...

Sheet pagos octubre 25
A1: DETALLE DE PAGOS EN BANCO
A2: MES DE OCTUBRE DE 2025
A4: Cuenta:Alborada 04-11-00-000468-4
A6: Fecha | B6: Recibo | C6: Descripción | D6: No.Casa | E6: Cobros | F6: Pagos | G6: Saldo total
A7: 45930 | C7: viene saldo anterior | G7: 5174.92
A8: 45931 | B8: 17944 | C8: YAPPY BG DE MARIET BROOKS SALAMANCA POR FliaBrooks casa 78 pago de seguridad sept y oct | D8: 78 | E8: 30 | G8: =+G7+E8+F8 -> 5204.92 | H8: a
A9: 45931 | B9: 17945 | C9: YAPPY BG DE SARALIZ LORENA HUSBAND DE VELASQUEZ POR casa 117 flia Velasquez mes de octubre | D9: 117 | E9: 15 | G9: =+G8+E9+F9 -> 5219.92 | H9: a
A10: 45931 | B10: 17946 | C10: ACH XPRESS - YOHANA MOLINAR- mes de octubre | D10: 113 | E10: 15 | G10: =+G9+E10+F10 -> 5234.92 | H10: a
A11: 45931 | B11: 17947 | C11: YAPPY BG DE JOSE DAVID BONILLA ALVARADO POR Septiembre 2025 Garita Casa D 14 Bonilla Gonz | D11: D-14 | E11: 15 | G11: =+G10+E11+F11 -> 5249.92 | H11: a
A12: 45931 | B12: 17948 | C12: BANCA MOVIL TRANSFERENCIA DE ROSEMENE SERVILIUS -mes de septiembre | D12: 182 | E12: 15 | G12: =+G11+E12+F12 -> 5264.92 | H12: a
A13: 45931 | B13: 17949 | C13: YAPPY BG DE ISAIAS FRANCISCO TATE BENJAMIN POR Seguridad y Mante Tate casa 239 mes Ago y septiembre | D13: 239 | E13: 30 | G13: =+G12+E13+F13 -> 5294.92 | H13: a
A14: 45931 | B14: 17950 | C14: BANCA MOVIL TRANSFERENCIA DE NATIVIDAD VALENCIA de JIMENEZ Pago mes de Septiembre Casa 26 | D14: 26 | E14: 15 | G14: =+G13+E14+F14 -> 5309.92 | H14: a
A15: 45931 | B15: 17951 | C15: YAPPY BG DE YUMITZIE ANNELIS HARWOOD de CEDEÑO POR mes de septiembre Flia Cedeno 192 | D15: 192 | E15: 15 | G15: =+G14+E15+F15 -> 5324.92 | H15: a
A16: 45931 | B16: 17952 | C16: YAPPY BG DE KASHMAH SHAMMETH CADOGAN de LEWIS POR mensualidad casa150 mes de julio | D16: 150 | E16: 15 | G16: =+G15+E16+F16 -> 5339.92 | H16: a
A17: 45931 | B17: 17953 | C17: YAPPY BG DE ANSELMO EMILIANO FORDE CHRISTOPHER- mes de octubre | D17: 5 | E17: 15 | G17: =+G16+E17+F17 -> 5354.92 | H17: a
A18: 45931 | B18: 17954 | C18: YAPPY BG DE HECTOR GABRIEL IBARGUEN MURILLO POR flia Ibarguen Ceballos mes septiembre | D18: 21 | E18: 15 | G18: =+G17+E18+F18 -> 5369.92 | H18: a
A19: 45931 | B19: PAGOS | C19: BANCA MOVIL TRANSFERENCIA A 0338011480674 TIGER SECURITY COMPANY AND TRAINING CENTER, S.A. | D19: PAGOS | E19: 0 | F19: -1819 | G19: =+G18+E19+F19 -> 3550.92 | H19: a
A20: 45931 | B20: 17955 | C20: BANCA MOVIL TRANSFERENCIA DE NILKA LORENA DEL CASTILLO ZELAYA casa 135- MES DE MAYO | D20: 135 | E20: 15 | G20: =+G19+E20+F20 -> 3565.92 | H20: a
A21: 45932 | B21: 17956 | C21: BANCA MOVIL TRANSFERENCIA DE JANINA ANGELINNA BORELLY de MELO Pago de oct nov dic casa 279 | D21: 279 | E21: 45 | G21: =+G20+E21+F21 -> 3610.92 | H21: a
A22: 45932 | B22: PAGOS | C22: BANCA MOVIL TRANSFERENCIA A 0454000010658 JOSE ALBERTO MARCIAGA BRAVO Materiales | D22: PAGOS | E22: 0 | F22: -15 | G22: =+G21+E22+F22 -> 3595.92 | H22: a
A23: 45932 | B23: 17957 | C23: YAPPY BG DE YURIBETH YAILYN LEE Casa 64 Familia Lee, Sep -Oct - Nov - Dic | D23: 64 | E23: 60 | G23: =+G22+E23+F23 -> 3655.92 | H23: a
A24: 45933 | B24: 17958 | C24: YAPPY BG DE ELOISA MALENY JAEN GUTIERREZ- MES DE AGOSTO | D24: 185 | E24: 15 | G24: =+G23+E24+F24 -> 3670.92 | H24: a
A25: 45933 | B25: 17959 | C25: YAPPY BG DE YELITZA YOLANY NORSE DE LA ESPADA POR pago Casa 318 - Agosto y Septiembre 202 | D25: 318 | E25: 30 | G25: =+G24+E25+F25 -> 3700.92 | H25: a
A26: 45933 | B26: 17960 | C26: YAPPY BG DE SHANI NG de CHIU POR Pago de Octubre familia Chiu casa 292 | D26: 292 | E26: 15 | G26: =+G25+E26+F26 -> 3715.92 | H26: a
A27: 45933 | B27: 17961 | C27: DEPOSITO -FLIA MURDOCK - MES DE SEPTIEMBRE | D27: 95 | E27: 15 | G27: =+G26+E27+F27 -> 3730.92 | H27: a
A28: 45933 | B28: 17962 | C28: BANCA MOVIL TRANSFERENCIA DE YOLANDA MAGALI CAMPOS GONZALEZ seguridad octubre 2025 | D28: 304 | E28: 15 | G28: =+G27+E28+F28 -> 3745.92 | H28: a
A29: 45933 | B29: 17963 | C29: YAPPY BG DE JAIME DAVID ANDERSON SINCLAIR- MES DE SEPTIEMBRE | D29: 172 | E29: 15 | G29: =+G28+E29+F29 -> 3760.92 | H29: a
A30: 45933 | B30: 17964 | C30: YAPPY BG DE EMELINA IVETT CATUY ALARCON- MES DE JULIO | D30: 68 | E30: 15 | G30: =+G29+E30+F30 -> 3775.92 | H30: a
A31: 45933 | B31: PAGOS | C31: BANCA MOVIL BAC INTERNATIONAL BANK 104349105 DISTRIBUIDORA GSQ PANAMA | D31: PAGOS | E31: 0 | F31: -213.52 | G31: =+G30+E31+F31 -> 3562.4 | H31: a
A32: 45933 | B32: 17965 | C32: YAPPY BG DE YANETH YAMILKA BADILLA PINEDA POR casa 157 octubre | D32: 157 | E32: 15 | G32: =+G31+E32+F32 -> 3577.4 | H32: a
A33: 45934 | B33: 17966 | C33: BANCA MOVIL TRANSFERENCIA DE ALIZA EMERITA JIMENEZ- MES DE OCTUBRE | D33: 30 | E33: 15 | G33: =+G32+E33+F33 -> 3592.4 | H33: a
A34: 45934 | B34: 17967 | C34: YAPPY BG DE AURA MERCEDES PINEDA de SANTAMARIA POR Casa 31 Familia Santamaria - MAYO, JUNIO, JULIO, AGOSTO, SEPTIEMBRE Y OCTUBRE | D34: 31 | E34: 90 | G34: =+G33+E34+F34 -> 3682.4 | H34: a
A35: 45934 | B35: TARJETAS | C35: YAPPY BG DE NELSON AZARIAS MORENO MAGDALENO POR - 3 TARJETAS CASA 310 | D35: TARJETAS | E35: 30 | G35: =+G34+E35+F35 -> 3712.4 | H35: a
A36: 45934 | B36: 17968 | C36: YAPPY BG DE NELSON AZARIAS MORENO MAGDALENO POR buen dia15 mes de oct 30 3 tarjeta de CASA 310 | D36: 310 | E36: 15 | G36: =+G35+E36+F36 -> 3727.4 | H36: a
A37: 45934 | B37: 17969 | C37: YAPPY BG DE YARITZA YAMILKA COOPER CHIFUNDO POR Casa 202 SChifundoYCooper mes de Sept 202 | D37: 202 | E37: 15 | G37: =+G36+E37+F37 -> 3742.4 | H37: a
A38: 45934 | B38: 17970 | C38: BANCA MOVIL TRANSFERENCIA DE EDWIN JAVIER ESCOBAR ROBINSON (YOUR PLUG) Flia Parris ENERO DE JUNIO | D38: 286 | E38: 90 | G38: =+G37+E38+F38 -> 3832.4 | H38: a
A39: 45934 | B39: 17971 | C39: YAPPY BG DE GUILLERMO CHALHOUB RODRIGUEZ POR Sept y Oct 2025 Casa 250 Alborada | D39: 250 | E39: 30 | G39: =+G38+E39+F39 -> 3862.4 | H39: a
A40: 45934 | B40: PAGOS | C40: YAPPY BG A MELVIN CARLTON FOSTER GALASTICA POR CORTE DE PARQUES | D40: PAGOS | E40: 0 | F40: -60 | G40: =+G39+E40+F40 -> 3802.4 | H40: a
A41: 45934 | B41: 17972 | C41: YAPPY BG DE VIELKA LUZMILA CUSATTI ANAYA - MES DE NOVIEMBRE | D41: 20 | E41: 15 | G41: =+G40+E41+F41 -> 3817.4 | H41: a
A42: 45934 | B42: 17973 | C42: YAPPY BG DE ARTURO ROGELIO ROBINSON WILLIAMS POR Pago de Sept a Dic 2025 casa 173 Flia Ro | D42: 173 | E42: 60 | G42: =+G41+E42+F42 -> 3877.4 | H42: a
...

Sheet pagos noviembre
A1: DETALLE DE PAGOS EN BANCO
A2: MES DE NOVIEMBRE DE 2025
A4: Cuenta:Alborada 04-11-00-000468-4
A6: Fecha | B6: Recibo | C6: Descripción | D6: No.Casa | E6: Cobros | F6: Pagos | G6: Saldo total
A7: 45961 | C7: viene saldo anterior | G7: =+'pagos octubre 25'!G200 -> 4252.56 | H7: a
A8: 45962 | B8: 18034 | C8: EFECTIVO- FLIA MENDOZA - NOVIEMBRE Y DICIEMBRE | D8: 244 | E8: 30 | G8: =+G7+E8+F8 -> 4282.56 | H8: a
